<?xml version="1.0" ?>
<!-- =================================================================================== -->
<!-- |    This document was autogenerated by xacro from src/arduinobot_description/urdf/arduinobot.urdf.xacro | -->
<!-- |    EDITING THIS FILE BY HAND IS NOT RECOMMENDED                                 | -->
<!-- =================================================================================== -->
<robot name="arduinobot">
  <!-- Links -->
  <link name="world"/>
  <link name="base_link">
    <visual>
      <origin rpy="0 0 0" xyz="-0.5 -0.5 0"/>
      <geometry>
        <mesh filename="package://arduinobot_description/mesh/basement.STL" scale="0.01 0.01 0.01"/>
      </geometry>
    </visual>
  </link>
  <link name="base_plate">
    <visual>
      <origin rpy="0 0 0" xyz="-0.39 -0.39 -0.56"/>
      <geometry>
        <mesh filename="package://arduinobot_description/mesh/base_plate.STL" scale="0.01 0.01 0.01"/>
      </geometry>
    </visual>
  </link>
  <link name="forward_drive_arm">
    <visual>
      <origin rpy=" 0 -1.570796326795 1.570796326795" xyz="0.19 0.06 -0.08"/>
      <geometry>
        <mesh filename="package://arduinobot_description/mesh/forward_drive_arm.STL" scale="0.01 0.01 0.01"/>
      </geometry>
    </visual>
  </link>
  <link name="horizontal_arm">
    <visual>
      <origin rpy="1.570796326795 0 1.570796326795" xyz="-0.03 -0.4 -0.06"/>
      <geometry>
        <mesh filename="package://arduinobot_description/mesh/horizontal_arm.STL" scale="0.01 0.01 0.01"/>
      </geometry>
    </visual>
  </link>
  <link name="claw_support">
    <visual>
      <origin rpy="0 0 1.570796326795" xyz="0 -0.05 -0.15"/>
      <geometry>
        <mesh filename="package://arduinobot_description/mesh/claw_support.STL" scale="0.01 0.01 0.01"/>
      </geometry>
    </visual>
  </link>
  <link name="gripper_right">
    <visual>
      <origin rpy="0 0 -1.570796326795" xyz="-0.1 0.50 -0.1"/>
      <geometry>
        <mesh filename="package://arduinobot_description/mesh/right_finger.STL" scale="0.01 0.01 0.01"/>
      </geometry>
    </visual>
  </link>
  <link name="gripper_left">
    <visual>
      <origin rpy="0 0 -1.570796326795" xyz="-0.04 0.50 -0.1"/>
      <geometry>
        <mesh filename="package://arduinobot_description/mesh/left_finger.STL" scale="0.01 0.01 0.01"/>
      </geometry>
    </visual>
  </link>
  <link name="tool_link"/>
  <!-- Joints -->
  <joint name="virtual_joint" type="fixed">
    <parent link="world"/>
    <child link="base_link"/>
    <origin rpy="0 0 0" xyz="0 0 0"/>
  </joint>
  <joint name="joint_1" type="revolute">
    <parent link="base_link"/>
    <child link="base_plate"/>
    <origin xyz="0 0 0.307"/>
    <axis xyz="0 0 1"/>
    <limit effort="30" lower="-1.570796326795" upper="1.570796326795" velocity="10"/>
  </joint>
  <joint name="joint_2" type="revolute">
    <parent link="base_plate"/>
    <child link="forward_drive_arm"/>
    <origin xyz="-0.02 0 0.35"/>
    <axis xyz="1 0 0"/>
    <limit effort="30" lower="-1.570796326795" upper="1.570796326795" velocity="10"/>
  </joint>
  <joint name="joint_3" type="revolute">
    <parent link="forward_drive_arm"/>
    <child link="horizontal_arm"/>
    <origin xyz="0 0 0.8"/>
    <axis xyz="1 0 0"/>
    <limit effort="30" lower="-1.570796326795" upper="1.570796326795" velocity="10"/>
  </joint>
  <joint name="horizontal_arm_to_claw_support" type="fixed">
    <parent link="horizontal_arm"/>
    <child link="claw_support"/>
    <origin xyz="0 0.82 0"/>
  </joint>
  <joint name="joint_4" type="revolute">
    <parent link="claw_support"/>
    <child link="gripper_right"/>
    <origin xyz="-0.04 0.13 -0.1"/>
    <axis xyz="0 0 1"/>
    <limit effort="30" lower="-1.570796326795" upper="0" velocity="10"/>
  </joint>
  <joint name="joint_5" type="revolute">
    <parent link="claw_support"/>
    <child link="gripper_left"/>
    <origin xyz="-0.22 0.13 -0.1"/>
    <axis xyz="0 0 1"/>
    <limit effort="30" lower="0" upper="1.570796326795" velocity="10"/>
    <mimic joint="joint_4" multiplier="-1" offset="0"/>
  </joint>
  <joint name="gripper_right_to_tool" type="fixed">
    <parent link="gripper_right"/>
    <child link="tool_link"/>
    <origin xyz="0 0 0"/>
  </joint>
</robot>

